#### async`函数接收到返回的值，发现不是`异常`或者`reject`，则判定成功，这里可以`return`各种数据类型的值，`false`,`NaN`,`undefined`...总之，都是`resolve

# 但是返回如下结果会使`async`函数判定失败`reject`

1. 内部含有直接使用并且未声明的变量或者函数。
2. 内部抛出一个错误`throw new Error`或者返回`reject`状态`return Promise.reject('执行失败')`
3. 函数方法执行出错（🌰：Object使用push()）等等...

# 当出现多个await连续调用时

上一个await出现错误导致整个async函数**停止运行**，其返回的promise对象reject

所以需要使用try catch包裹await进行错误处理，做好兜底逻辑防止出现错误后影响接下来的调用



# 若 Promise 处理异常(rejected)，await 表达式会把 Promise 的异常原因抛出。

```js
async function f3() {
  try {
    var z = await Promise.reject(30);
  } catch (e) {
    console.log(e); // 30
  }
}
f3();
Copy to Clipboard

```





//作者：大Y
链接：https://juejin.cn/post/6844903621360943118
来源：稀土掘金
著作权归作者所有。商业转载请联系作者获得授权，非商业转载请注明出处。